<?xml version="1.0" encoding="utf-8"?>
<!-- This URDF was automatically created by SolidWorks to URDF Exporter! Originally created by Stephen Brawner (brawner@gmail.com) 
     Commit Version: 1.6.0-4-g7f85cfe  Build Version: 1.6.7995.38578
     For more information, please see http://wiki.ros.org/sw_urdf_exporter -->
<robot
  name="manipulator">
  <link name="dummy_link">
  <pose>"0 0 0 0 0 0"</pose>
  </link>
  <joint name="dummy_joint" type="fixed">
    <parent link="dummy_link" />
    <child link="base_link" />
    <origin xyz = "0 0 0" rpy= "0 0 0" />
    <axis xyz = "0 0 0" />
  </joint>
  <link
    name="base_link">
    <inertial>
      <origin
        xyz="-0.0211776996618438 -1.22728266438443E-08 0.220694894832878"
        rpy="0 0 0" />
      <mass
        value="31.440945977861" />
      <inertia
        ixx="0.303296482329575"
        ixy="-1.67101174915287E-06"
        ixz="0.0507896153372789"
        iyy="2.55073722062815"
        iyz="2.13037549899861E-08"
        izz="2.73494594645884" />
    </inertial>
    <visual>
      <origin
        xyz="0 0 0"
        rpy="0 0 0" />
      <geometry>
        <mesh
          filename="package://manipulator/meshes/base_link.STL" />
      </geometry>
      <material
        name="">
        <color
          rgba="0.792156862745098 0.819607843137255 0.933333333333333 1" />
      </material>
    </visual>
    <collision>
      <origin
        xyz="0 0 0"
        rpy="0 0 0" />
      <geometry>
        <mesh
          filename="package://manipulator/meshes/base_link.STL" />
      </geometry>
    </collision>
  </link>
  <link
    name="rear_shaft">
    <inertial>
      <origin
        xyz="-1.11022302462516E-16 0 0.254"
        rpy="0 0 0" />
      <mass
        value="1.02790122650355" />
      <inertia
        ixx="0.0222708703975125"
        ixy="1.05879118406788E-20"
        ixz="7.30648942347479E-20"
        iyy="0.0222708703975125"
        iyz="1.28838771050466E-19"
        izz="0.000331023775623048" />
    </inertial>
    <visual>
      <origin
        xyz="0 0 0"
        rpy="0 0 0" />
      <geometry>
        <mesh
          filename="package://manipulator/meshes/rear_shaft.STL" />
      </geometry>
      <material
        name="">
        <color
          rgba="0.792156862745098 0.819607843137255 0.933333333333333 1" />
      </material>
    </visual>
    <collision>
      <origin
        xyz="0 0 0"
        rpy="0 0 0" />
      <geometry>
        <mesh
          filename="package://manipulator/meshes/rear_shaft.STL" />
      </geometry>
    </collision>
  </link>
  <joint
    name="rear_shaft_joint"
    type="continuous">
    <origin
      xyz="-0.254678481031125 -0.254000153585616 0.1016"
      rpy="-1.5707963267949 0 0" />
    <parent
      link="base_link" />
    <child
      link="rear_shaft" />
    <axis
      xyz="0 0 -1" />
  </joint>
  <link
    name="rear_right_wheel">
    <inertial>
      <origin
        xyz="-8.79605066561595E-09 3.52349549537223E-09 0.0254000563127965"
        rpy="0 0 0" />
      <mass
        value="0.627305726641921" />
      <inertia
        ixx="0.00204148062072574"
        ixy="1.19734260311977E-09"
        ixz="-7.48969655149847E-11"
        iyy="0.00204147729457848"
        iyz="2.87979816380951E-11"
        izz="0.00389311509621041" />
    </inertial>
    <visual>
      <origin
        xyz="0 0 0"
        rpy="0 0 0" />
      <geometry>
        <mesh
          filename="package://manipulator/meshes/rear_right_wheel.STL" />
      </geometry>
      <material
        name="">
        <color
          rgba="0.792156862745098 0.819607843137255 0.933333333333333 1" />
      </material>
    </visual>
    <collision>
      <origin
        xyz="0 0 0"
        rpy="0 0 0" />
      <geometry>
        <mesh
          filename="package://manipulator/meshes/rear_right_wheel.STL" />
      </geometry>
    </collision>
  </link>
  <joint
    name="rear_right_wheel_joint"
    type="continuous">
    <origin
      xyz="0 0 0"
      rpy="0 0 0" />
    <parent
      link="rear_shaft" />
    <child
      link="rear_right_wheel" />
    <axis
      xyz="0 0 -1" />
  </joint>
  <link
    name="rear_left_wheel">
    <inertial>
      <origin
        xyz="-9.37474553541762E-09 1.37828781721083E-09 -0.0253999436872031"
        rpy="0 0 0" />
      <mass
        value="0.627305726641925" />
      <inertia
        ixx="0.00204147989803352"
        ixy="1.82074875298365E-09"
        ixz="-7.95440770898799E-11"
        iyy="0.00204147801727073"
        iyz="1.05649829318396E-11"
        izz="0.00389311509621043" />
    </inertial>
    <visual>
      <origin
        xyz="0 0 0"
        rpy="0 0 0" />
      <geometry>
        <mesh
          filename="package://manipulator/meshes/rear_left_wheel.STL" />
      </geometry>
      <material
        name="">
        <color
          rgba="0.792156862745098 0.819607843137255 0.933333333333333 1" />
      </material>
    </visual>
    <collision>
      <origin
        xyz="0 0 0"
        rpy="0 0 0" />
      <geometry>
        <mesh
          filename="package://manipulator/meshes/rear_left_wheel.STL" />
      </geometry>
    </collision>
  </link>
  <joint
    name="rear_left_wheel_joint"
    type="fixed">
    <origin
      xyz="0 0 0.508"
      rpy="0 0 0" />
    <parent
      link="rear_shaft" />
    <child
      link="rear_left_wheel" />
    <axis
      xyz="0 0 -1" />
  </joint>
  <link
    name="front_right_shaft">
    <inertial>
      <origin
        xyz="-0.0431205113179054 5.17185116954977E-09 0.0239485321305914"
        rpy="0 0 0" />
      <mass
        value="0.535359913631541" />
      <inertia
        ixx="0.000836353410948497"
        ixy="-6.15885540479402E-10"
        ixz="-0.000555136856499355"
        iyy="0.00217714694801786"
        iyz="-5.81341875436344E-10"
        izz="0.00151373754697996" />
    </inertial>
    <visual>
      <origin
        xyz="0 0 0"
        rpy="0 0 0" />
      <geometry>
        <mesh
          filename="package://manipulator/meshes/front_right_shaft.STL" />
      </geometry>
      <material
        name="">
        <color
          rgba="0.792156862745098 0.819607843137255 0.933333333333333 1" />
      </material>
    </visual>
    <collision>
      <origin
        xyz="0 0 0"
        rpy="0 0 0" />
      <geometry>
        <mesh
          filename="package://manipulator/meshes/front_right_shaft.STL" />
      </geometry>
    </collision>
  </link>
  <joint
    name="front_right_shaft_joint"
    type="continuous">
    <origin
      xyz="0.253321518968875 -0.101600153585616 0.1016"
      rpy="0 0 1.5707963267949" />
    <parent
      link="base_link" />
    <child
      link="front_right_shaft" />
    <axis
      xyz="0 0 1" />
  </joint>
  <link
    name="front_right_wheel">
    <inertial>
      <origin
        xyz="-9.41724098701968E-09 3.76971070560339E-05 0.0254000563127964"
        rpy="0 0 0" />
      <mass
        value="0.627305726641923" />
      <inertia
        ixx="0.00204147976835884"
        ixy="1.88207273872621E-09"
        ixz="-7.98651082560103E-11"
        iyy="0.00204147814694538"
        iyz="7.77454306124795E-12"
        izz="0.00389311509621041" />
    </inertial>
    <visual>
      <origin
        xyz="0 0 0"
        rpy="0 0 0" />
      <geometry>
        <mesh
          filename="package://manipulator/meshes/front_right_wheel.STL" />
      </geometry>
      <material
        name="">
        <color
          rgba="0.792156862745098 0.819607843137255 0.933333333333333 1" />
      </material>
    </visual>
    <collision>
      <origin
        xyz="0 0 0"
        rpy="0 0 0" />
      <geometry>
        <mesh
          filename="package://manipulator/meshes/front_right_wheel.STL" />
      </geometry>
    </collision>
  </link>
  <joint
    name="front_right_wheel_joint"
    type="fixed">
    <origin
      xyz="-0.1524 0 -3.76960577197494E-05"
      rpy="-1.5707963267949 0 -1.5707963267949" />
    <parent
      link="front_right_shaft" />
    <child
      link="front_right_wheel" />
    <axis
      xyz="0 1 0" />
  </joint>
  <link
    name="front_left_shaft">
    <inertial>
      <origin
        xyz="0.0431205113179056 -5.17185116954977E-09 0.0239485321305912"
        rpy="0 0 0" />
      <mass
        value="0.53535991363154" />
      <inertia
        ixx="0.000836353410948491"
        ixy="-6.15885539623722E-10"
        ixz="0.000555136856499352"
        iyy="0.00217714694801786"
        iyz="5.81341875066337E-10"
        izz="0.00151373754697996" />
    </inertial>
    <visual>
      <origin
        xyz="0 0 0"
        rpy="0 0 0" />
      <geometry>
        <mesh
          filename="package://manipulator/meshes/front_left_shaft.STL" />
      </geometry>
      <material
        name="">
        <color
          rgba="0.792156862745098 0.819607843137255 0.933333333333333 1" />
      </material>
    </visual>
    <collision>
      <origin
        xyz="0 0 0"
        rpy="0 0 0" />
      <geometry>
        <mesh
          filename="package://manipulator/meshes/front_left_shaft.STL" />
      </geometry>
    </collision>
  </link>
  <joint
    name="front_left_shaft_joint"
    type="continuous">
    <origin
      xyz="0.253321518968875 0.101599846414384 0.1016"
      rpy="0 0 1.5707963267949" />
    <parent
      link="base_link" />
    <child
      link="front_left_shaft" />
    <axis
      xyz="0 0 1" />
  </joint>
  <link
    name="front_left_wheel">
    <inertial>
      <origin
        xyz="-9.41724054293047E-09 3.76971070559229E-05 -0.0253999436872032"
        rpy="0 0 0" />
      <mass
        value="0.627305726641925" />
      <inertia
        ixx="0.00204147976835886"
        ixy="1.88207274048894E-09"
        ixz="-7.98651083867113E-11"
        iyy="0.00204147814694539"
        iyz="7.77454374069249E-12"
        izz="0.00389311509621043" />
    </inertial>
    <visual>
      <origin
        xyz="0 0 0"
        rpy="0 0 0" />
      <geometry>
        <mesh
          filename="package://manipulator/meshes/front_left_wheel.STL" />
      </geometry>
      <material
        name="">
        <color
          rgba="0.792156862745098 0.819607843137255 0.933333333333333 1" />
      </material>
    </visual>
    <collision>
      <origin
        xyz="0 0 0"
        rpy="0 0 0" />
      <geometry>
        <mesh
          filename="package://manipulator/meshes/front_left_wheel.STL" />
      </geometry>
    </collision>
  </link>
  <joint
    name="front_left_wheel_joint"
    type="fixed">
    <origin
      xyz="0.1524 0 -3.76960577197494E-05"
      rpy="-1.5707963267949 0 -1.5707963267949" />
    <parent
      link="front_left_shaft" />
    <child
      link="front_left_wheel" />
    <axis
      xyz="-1 0 0" />
  </joint>
  <link
    name="manipulator_base">
    <inertial>
      <origin
        xyz="1.20570220474292E-13 4.77395900588817E-14 0.0221577186195164"
        rpy="0 0 0" />
      <mass
        value="0.343652649470195" />
      <inertia
        ixx="0.000931840317732508"
        ixy="-3.93117586115653E-19"
        ixz="2.41532900673122E-18"
        iyy="0.000931840317732507"
        iyz="8.20324158237791E-18"
        izz="0.00144684523805802" />
    </inertial>
    <visual>
      <origin
        xyz="0 0 0"
        rpy="0 0 0" />
      <geometry>
        <mesh
          filename="package://manipulator/meshes/manipulator_base.STL" />
      </geometry>
      <material
        name="">
        <color
          rgba="0.792156862745098 0.819607843137255 0.933333333333333 1" />
      </material>
    </visual>
    <collision>
      <origin
        xyz="0 0 0"
        rpy="0 0 0" />
      <geometry>
        <mesh
          filename="package://manipulator/meshes/manipulator_base.STL" />
      </geometry>
    </collision>
  </link>
  <joint
    name="manipulator_base_joint"
    type="fixed">
    <origin
      xyz="0.354921518968873 -0.00035241085596216 0.2667"
      rpy="0 0 1.5707963267949" />
    <parent
      link="base_link" />
    <child
      link="manipulator_base" />
    <axis
      xyz="0 0 0" />
  </joint>
  <link
    name="link1">
    <inertial>
      <origin
        xyz="-0.00476743254742651 0 0.0577748363838581"
        rpy="0 0 0" />
      <mass
        value="1.48027865388571" />
      <inertia
        ixx="0.00299692664042462"
        ixy="-2.23569703188312E-09"
        ixz="1.3154618503852E-06"
        iyy="0.00394348618991032"
        iyz="-1.84484036222152E-10"
        izz="0.00298109357001247" />
    </inertial>
    <visual>
      <origin
        xyz="0 0 0"
        rpy="0 0 0" />
      <geometry>
        <mesh
          filename="package://manipulator/meshes/link1.STL" />
      </geometry>
      <material
        name="">
        <color
          rgba="0.792156862745098 0.819607843137255 0.933333333333333 1" />
      </material>
    </visual>
    <collision>
      <origin
        xyz="0 0 0"
        rpy="0 0 0" />
      <geometry>
        <mesh
          filename="package://manipulator/meshes/link1.STL" />
      </geometry>
    </collision>
  </link>
  <joint
    name="link1_joint"
    type="continuous">
    <origin
      xyz="0 0 0.083058"
      rpy="0 0.0823309272452037 1.4401673322326" />
    <parent
      link="manipulator_base" />
    <child
      link="link1" />
    <axis
      xyz="-0.082237947023427 0 0.996612723212669" />
  </joint>
  <link
    name="link2">
    <inertial>
      <origin
        xyz="-4.69402294811516E-13 0.152399999999151 -0.0889000000000042"
        rpy="0 0 0" />
      <mass
        value="2.62571951129597" />
      <inertia
        ixx="0.0366190533392522"
        ixy="4.47233396150271E-18"
        ixz="-1.73472347597681E-18"
        iyy="0.00343981383550577"
        iyz="5.57008866114428E-18"
        izz="0.0397646852785769" />
    </inertial>
    <visual>
      <origin
        xyz="0 0 0"
        rpy="0 0 0" />
      <geometry>
        <mesh
          filename="package://manipulator/meshes/link2.STL" />
      </geometry>
      <material
        name="">
        <color
          rgba="0.792156862745098 0.819607843137255 0.933333333333333 1" />
      </material>
    </visual>
    <collision>
      <origin
        xyz="0 0 0"
        rpy="0 0 0" />
      <geometry>
        <mesh
          filename="package://manipulator/meshes/link2.STL" />
      </geometry>
    </collision>
  </link>
  <joint
    name="link2_joint"
    type="revolute">
    <origin
      xyz="-0.0081465 -0.0889 0.098724"
      rpy="1.5708 0 0" />
    <parent
      link="link1" />
    <child
      link="link2" />
    <axis
      xyz="0 0 -1" />
    <limit
      lower="1.86"
      upper="-2.18"
      effort="10"
      velocity="1000" />
  </joint>
  <link
    name="link3">
    <inertial>
      <origin
        xyz="0.148003295006309 -0.0357219733124967 -0.0889000000000043"
        rpy="0 0 0" />
      <mass
        value="2.88590691059082" />
      <inertia
        ixx="0.00605684364244081"
        ixy="0.00751256389339986"
        ixz="-2.22261445359528E-17"
        iyy="0.035369674312202"
        iyz="2.81892564846231E-18"
        izz="0.0402180502620228" />
    </inertial>
    <visual>
      <origin
        xyz="0 0 0"
        rpy="0 0 0" />
      <geometry>
        <mesh
          filename="package://manipulator/meshes/link3.STL" />
      </geometry>
      <material
        name="">
        <color
          rgba="0.792156862745098 0.819607843137255 0.933333333333333 1" />
      </material>
    </visual>
    <collision>
      <origin
        xyz="0 0 0"
        rpy="0 0 0" />
      <geometry>
        <mesh
          filename="package://manipulator/meshes/link3.STL" />
      </geometry>
    </collision>
  </link>
  <joint
    name="link3_joint"
    type="revolute">
    <origin
      xyz="0 0.3048 0"
      rpy="0 0 0" />
    <parent
      link="link2" />
    <child
      link="link3" />
    <axis
      xyz="0 0 1" />
    <limit
      lower="3.14"
      upper="-0.14"
      effort="10"
      velocity="1000" />
  </joint>
  <link
    name="link4">
    <inertial>
      <origin
        xyz="0.0410887868371235 2.8121622031696E-05 -0.0888999860575093"
        rpy="0 0 0" />
      <mass
        value="1.48027855179196" />
      <inertia
        ixx="0.00298098362629461"
        ixy="-1.09936009905687E-08"
        ixz="8.33647750494732E-10"
        iyy="0.0029970335065252"
        iyz="2.33216838036414E-09"
        izz="0.00394348692572763" />
    </inertial>
    <visual>
      <origin
        xyz="0 0 0"
        rpy="0 0 0" />
      <geometry>
        <mesh
          filename="package://manipulator/meshes/link4.STL" />
      </geometry>
      <material
        name="">
        <color
          rgba="0.792156862745098 0.819607843137255 0.933333333333333 1" />
      </material>
    </visual>
    <collision>
      <origin
        xyz="0 0 0"
        rpy="0 0 0" />
      <geometry>
        <mesh
          filename="package://manipulator/meshes/link4.STL" />
      </geometry>
    </collision>
  </link>
  <joint
    name="link4_joint"
    type="revolute">
    <origin
      xyz="0.29629 -0.071513 0"
      rpy="0 0 0" />
    <parent
      link="link3" />
    <child
      link="link4" />
    <axis
      xyz="0 0 -1" />
    <limit
      lower="2.35"
      upper="-1.77"
      effort="10"
      velocity="1000" />
  </joint>
  <link
    name="gripper">
    <inertial>
      <origin
        xyz="-0.00381509857258 0.0733141735781111 -2.73245616080331E-05"
        rpy="0 0 0" />
      <mass
        value="0.318053344407251" />
      <inertia
        ixx="0.00117130768739902"
        ixy="8.77342735524937E-07"
        ixz="-3.30840192944662E-10"
        iyy="0.00116301084919414"
        iyz="-1.13226117227878E-09"
        izz="0.0011600211189812" />
    </inertial>
    <visual>
      <origin
        xyz="0 0 0"
        rpy="0 0 0" />
      <geometry>
        <mesh
          filename="package://manipulator/meshes/gripper.STL" />
      </geometry>
      <material
        name="">
        <color
          rgba="0.792156862745098 0.819607843137255 0.933333333333333 1" />
      </material>
    </visual>
    <collision>
      <origin
        xyz="0 0 0"
        rpy="0 0 0" />
      <geometry>
        <mesh
          filename="package://manipulator/meshes/gripper.STL" />
      </geometry>
    </collision>
  </link>
  <joint
    name="gripper_joint"
    type="continuous">
    <origin
      xyz="0.248853265309693 0.00336707133293568 -0.0909728912537893"
      rpy="0 0.575281631239788 1.5707963267949" />
    <parent
      link="link4" />
    <child
      link="gripper" />
    <axis
      xyz="0.0005742505150447 -0.999999765788382 0.000372370147822085" />
  </joint>
  <link
    name="gripper_left">
    <inertial>
      <origin
        xyz="0.0394810399510597 -0.109811498641309 -0.00634999999984642"
        rpy="0 0 0" />
      <mass
        value="0.0811562982935577" />
      <inertia
        ixx="0.000402419693683614"
        ixy="9.97016527628495E-05"
        ixz="-1.35525271560688E-20"
        iyy="3.5590631452345E-05"
        iyz="-1.56701095242046E-19"
        izz="0.000435828708577331" />
    </inertial>
    <visual>
      <origin
        xyz="0 0 0"
        rpy="0 0 0" />
      <geometry>
        <mesh
          filename="package://manipulator/meshes/gripper_left.STL" />
      </geometry>
      <material
        name="">
        <color
          rgba="0.792156862745098 0.819607843137255 0.933333333333333 1" />
      </material>
    </visual>
    <collision>
      <origin
        xyz="0 0 0"
        rpy="0 0 0" />
      <geometry>
        <mesh
          filename="package://manipulator/meshes/gripper_left.STL" />
      </geometry>
    </collision>
  </link>
  <joint
    name="gripper_left_joint"
    type="revolute">
    <origin
      xyz="0.0127004769785455 -0.000826963988762031 -0.0208624359755367"
      rpy="-1.57079632680667 1.57042395663749 -1.57022207621871" />
    <parent
      link="gripper" />
    <child
      link="gripper_left" />
    <axis
      xyz="0 0 -1" />
      <limit
      lower="0.45"
      upper="-1.15"
      effort="10"
      velocity="1000" />
  </joint>
  <link
    name="gripper_right">
    <inertial>
      <origin
        xyz="0.11399724572148 0.0249388395349214 -0.0063499999999107"
        rpy="0 0 0" />
      <mass
        value="0.0811562982935572" />
      <inertia
        ixx="4.94791777175608E-05"
        ixy="-0.000121828774304379"
        ixz="2.10868852218958E-18"
        iyy="0.000388531147418396"
        iyz="6.03087458445062E-19"
        izz="0.000435828708577328" />
    </inertial>
    <visual>
      <origin
        xyz="0 0 0"
        rpy="0 0 0" />
      <geometry>
        <mesh
          filename="package://manipulator/meshes/gripper_right.STL" />
      </geometry>
      <material
        name="">
        <color
          rgba="0.792156862745098 0.819607843137255 0.933333333333333 1" />
      </material>
    </visual>
    <collision>
      <origin
        xyz="0 0 0"
        rpy="0 0 0" />
      <geometry>
        <mesh
          filename="package://manipulator/meshes/gripper_right.STL" />
      </geometry>
    </collision>
  </link>
  <joint
    name="gripper_right_joint"
    type="revolute">
    <origin
      xyz="0.012700468056301 -0.00081142668143086 0.0208630053929066"
      rpy="1.57079632680667 -1.57042395663749 1.57137057737108" />
    <parent
      link="gripper" />
    <child
      link="gripper_right" />
    <axis
      xyz="0 0 -1" />
      <limit
      lower="0.15"
      upper="-1.39"
      effort="10"
      velocity="1000" />
  </joint>
</robot>